<?xml version="1.0" ?>
<robot name="vinebot" xmlns:xacro="http://www.ros.org/wiki/xacro">

  <xacro:property name="clearance" value="0.0" />
  <xacro:arg name="use_nominal_extrinsics" default="false"/>

  <xacro:include filename="$(find vinebot_description)/urdf/materials.xacro" />
  <!-- <xacro:include filename="$(find vinebot_description)/urdf/vinebot.trans" /> -->
  <xacro:include filename="$(find vinebot_description)/urdf/vinebot.gazebo" />
  <!-- <xacro:include filename="$(find vinebot_description)/urdf/gazebo_control.xacro" /> -->
  <xacro:include filename="$(find vinebot_description)/urdf/ros2_control.xacro" />
  <!-- <xacro:include filename="$(find vinebot_description)/gazebo/vinebot_detailed_plugins.gazebo" /> -->
  <xacro:include filename="$(find vinebot_description)/urdf/vinebot_d455.urdf.xacro" />
  <xacro:include filename="$(find vinebot_description)/urdf/vinebot_livox_mid40.xacro" />
  <xacro:include filename="$(find vinebot_description)/urdf/imu.xacro" />

  <!-- base_footprint -->
  <link name="base_footprint">
    <visual>
      <origin xyz="0.35 0 0" rpy="0 0 0" />
      <geometry>
        <box size="0.9 0.6 0.001"/>
      </geometry>
      <material name="blue"/>
    </visual>
  </link>

  <joint name="base_footprint_to_base_link" type="fixed">
    <origin xyz="0 0 ${clearance}" rpy="0 0 0" />
    <parent link="base_footprint" />
    <child link="base_link" />
  </joint>

  <link name="base_link">
    <inertial>
      <origin rpy="0 0 0" xyz="0.3733685481948254 3.982448910416214e-05 0.15740777035883136"/>
      <mass value="76.37622695455383"/>
      <inertia ixx="1.647594" ixy="0.003226" ixz="0.018226" iyy="3.898909" iyz="0.003649" izz="4.783297"/>
    </inertial>
    <visual>
      <origin rpy="0 0 0" xyz="0 0 0"/>
      <geometry>
        <mesh filename="package://vinebot_description/meshes/base_link.stl" scale="0.001 0.001 0.001"/>
      </geometry>
      <material name="silver"/>
    </visual>
    <collision>
      <origin rpy="0 0 0" xyz="0 0 0"/>
      <geometry>
        <mesh filename="package://vinebot_description/meshes/base_link.stl" scale="0.001 0.001 0.001"/>
      </geometry>
    </collision>
  </link>

  <link name="right_back_1">
    <inertial>
      <origin rpy="0 0 0" xyz="-2.8410577210431776e-07 0.0016996659402881975 9.692134567140798e-08"/>
      <mass value="0.5239439717413419"/>
      <inertia ixx="0.000916" ixy="-0.0" ixz="-0.0" iyy="0.001378" iyz="0.0" izz="0.000916"/>
    </inertial>
    <visual>
      <origin rpy="0 0 0" xyz="-0.005176 0.204252 -0.133306"/>
      <geometry>
        <mesh filename="package://vinebot_description/meshes/right_back_1.stl" scale="0.001 0.001 0.001"/>
      </geometry>
      <material name="silver"/>
    </visual>
    <collision>
      <origin rpy="0 0 0" xyz="-0.005176 0.204252 -0.133306"/>
      <geometry>
        <mesh filename="package://vinebot_description/meshes/right_back_1.stl" scale="0.001 0.001 0.001"/>
      </geometry>
    </collision>
  </link>

  <link name="rubber_right_back_1">
    <inertial>
      <origin rpy="0 0 0" xyz="-3.907394383667259e-07 0.027000145829504024 2.0925773944191484e-07"/>
      <mass value="1.3322018275318805"/>
      <inertia ixx="0.008837" ixy="0.0" ixz="-0.0" iyy="0.015831" iyz="-0.0" izz="0.008837"/>
    </inertial>
    <visual>
      <origin rpy="0 0 0" xyz="-0.005176 0.230105 -0.133306"/>
      <geometry>
        <mesh filename="package://vinebot_description/meshes/rubber_right_back_1.stl" scale="0.001 0.001 0.001"/>
      </geometry>
      <material name="black"/>
    </visual>
    <collision>
      <origin rpy="0 0 0" xyz="-0.005176 0.230105 -0.133306"/>
      <geometry>
        <mesh filename="package://vinebot_description/meshes/rubber_right_back_1.stl" scale="0.001 0.001 0.001"/>
      </geometry>
    </collision>
  </link>

  <link name="left_back_1">
    <inertial>
      <origin rpy="0 0 0" xyz="-2.841058909094571e-07 0.011699665940287929 9.692152316831404e-08"/>
      <mass value="0.5239439717413419"/>
      <inertia ixx="0.000916" ixy="0.0" ixz="0.0" iyy="0.001378" iyz="0.0" izz="0.000916"/>
    </inertial>
    <visual>
      <origin rpy="0 0 0" xyz="-0.005176 -0.195748 -0.133306"/>
      <geometry>
        <mesh filename="package://vinebot_description/meshes/left_back_1.stl" scale="0.001 0.001 0.001"/>
      </geometry>
      <material name="silver"/>
    </visual>
    <collision>
      <origin rpy="0 0 0" xyz="-0.005176 -0.195748 -0.133306"/>
      <geometry>
        <mesh filename="package://vinebot_description/meshes/left_back_1.stl" scale="0.001 0.001 0.001"/>
      </geometry>
    </collision>
  </link>

  <link name="rubber_left_back_1">
    <inertial>
      <origin rpy="0 0 0" xyz="-2.212191398702143e-07 -0.026999813948927948 -4.462515007519485e-08"/>
      <mass value="1.3322018275318805"/>
      <inertia ixx="0.008837" ixy="-0.0" ixz="-0.0" iyy="0.015831" iyz="-0.0" izz="0.008837"/>
    </inertial>
    <visual>
      <origin rpy="0 0 0" xyz="-0.005176 -0.235 -0.133306"/>
      <geometry>
        <mesh filename="package://vinebot_description/meshes/rubber_left_back_1.stl" scale="0.001 0.001 0.001"/>
      </geometry>
      <material name="black"/>
    </visual>
    <collision>
      <origin rpy="0 0 0" xyz="-0.005176 -0.235 -0.133306"/>
      <geometry>
        <mesh filename="package://vinebot_description/meshes/rubber_left_back_1.stl" scale="0.001 0.001 0.001"/>
      </geometry>
    </collision>
  </link>

  <link name="right_front_1">
    <inertial>
      <origin rpy="0 0 0" xyz="2.132365639617717e-08 0.0016996659402878922 -3.301854983317476e-07"/>
      <mass value="0.5239439717413419"/>
      <inertia ixx="0.000916" ixy="0.0" ixz="-0.0" iyy="0.001378" iyz="-0.0" izz="0.000916"/>
    </inertial>
    <visual>
      <origin rpy="0 0 0" xyz="-0.716 0.204252 -0.133748"/>
      <geometry>
        <mesh filename="package://vinebot_description/meshes/right_front_1.stl" scale="0.001 0.001 0.001"/>
      </geometry>
      <material name="silver"/>
    </visual>
    <collision>
      <origin rpy="0 0 0" xyz="-0.716 0.204252 -0.133748"/>
      <geometry>
        <mesh filename="package://vinebot_description/meshes/right_front_1.stl" scale="0.001 0.001 0.001"/>
      </geometry>
    </collision>
  </link>

  <link name="rubber_right_front_1">
    <inertial>
      <origin rpy="0 0 0" xyz="-1.2616058797654262e-07 -0.026999813948928142 -2.828716338387771e-07"/>
      <mass value="1.3322018275318805"/>
      <inertia ixx="0.008837" ixy="-0.0" ixz="-0.0" iyy="0.015831" iyz="0.0" izz="0.008837"/>
    </inertial>
    <visual>
      <origin rpy="0 0 0" xyz="-0.716 0.175 -0.133748"/>
      <geometry>
        <mesh filename="package://vinebot_description/meshes/rubber_right_front_1.stl" scale="0.001 0.001 0.001"/>
      </geometry>
      <material name="black"/>
    </visual>
    <collision>
      <origin rpy="0 0 0" xyz="-0.716 0.175 -0.133748"/>
      <geometry>
        <mesh filename="package://vinebot_description/meshes/rubber_right_front_1.stl" scale="0.001 0.001 0.001"/>
      </geometry>
    </collision>
  </link>

  <link name="left_front_1">
    <inertial>
      <origin rpy="0 0 0" xyz="2.1323690035934817e-08 0.0016996659402879477 -3.301854323012332e-07"/>
      <mass value="0.5239439717413419"/>
      <inertia ixx="0.000916" ixy="0.0" ixz="-0.0" iyy="0.001378" iyz="-0.0" izz="0.000916"/>
    </inertial>
    <visual>
      <origin rpy="0 0 0" xyz="-0.716 -0.205748 -0.133748"/>
      <geometry>
        <mesh filename="package://vinebot_description/meshes/left_front_1.stl" scale="0.001 0.001 0.001"/>
      </geometry>
      <material name="silver"/>
    </visual>
    <collision>
      <origin rpy="0 0 0" xyz="-0.716 -0.205748 -0.133748"/>
      <geometry>
        <mesh filename="package://vinebot_description/meshes/left_front_1.stl" scale="0.001 0.001 0.001"/>
      </geometry>
    </collision>
  </link>

  <link name="rubber_left_front_1">
    <inertial>
      <origin rpy="0 0 0" xyz="-1.0338399381026875e-07 0.02700014582950408 -2.38325770202108e-07"/>
      <mass value="1.3322018275318805"/>
      <inertia ixx="0.008837" ixy="0.0" ixz="-0.0" iyy="0.015831" iyz="0.0" izz="0.008837"/>
    </inertial>
    <visual>
      <origin rpy="0 0 0" xyz="-0.716 -0.179895 -0.133748"/>
      <geometry>
        <mesh filename="package://vinebot_description/meshes/rubber_left_front_1.stl" scale="0.001 0.001 0.001"/>
      </geometry>
      <material name="black"/>
    </visual>
    <collision>
      <origin rpy="0 0 0" xyz="-0.716 -0.179895 -0.133748"/>
      <geometry>
        <mesh filename="package://vinebot_description/meshes/rubber_left_front_1.stl" scale="0.001 0.001 0.001"/>
      </geometry>
    </collision>
  </link>

  <link name="rigth_middle_1">
    <inertial>
      <origin rpy="0 0 0" xyz="5.9225261972439824e-08 0.00169966594028792 -1.5836653072254236e-08"/>
      <mass value="0.5239439717413419"/>
      <inertia ixx="0.000916" ixy="-0.0" ixz="-0.0" iyy="0.001378" iyz="0.0" izz="0.000916"/>
    </inertial>
    <visual>
      <origin rpy="0 0 0" xyz="-0.361346 0.204252 -0.133643"/>
      <geometry>
        <mesh filename="package://vinebot_description/meshes/rigth_middle_1.stl" scale="0.001 0.001 0.001"/>
      </geometry>
      <material name="silver"/>
    </visual>
    <collision>
      <origin rpy="0 0 0" xyz="-0.361346 0.204252 -0.133643"/>
      <geometry>
        <mesh filename="package://vinebot_description/meshes/rigth_middle_1.stl" scale="0.001 0.001 0.001"/>
      </geometry>
    </collision>
  </link>

  <link name="rubber_rigth_middle_1">
    <inertial>
      <origin rpy="0 0 0" xyz="1.7472558466735677e-07 0.02700014582950408 -1.1903490726439259e-07"/>
      <mass value="1.3322018275318805"/>
      <inertia ixx="0.008837" ixy="-0.0" ixz="-0.0" iyy="0.015831" iyz="-0.0" izz="0.008837"/>
    </inertial>
    <visual>
      <origin rpy="0 0 0" xyz="-0.361346 0.230105 -0.133643"/>
      <geometry>
        <mesh filename="package://vinebot_description/meshes/rubber_rigth_middle_1.stl" scale="0.001 0.001 0.001"/>
      </geometry>
      <material name="black"/>
    </visual>
    <collision>
      <origin rpy="0 0 0" xyz="-0.361346 0.230105 -0.133643"/>
      <geometry>
        <mesh filename="package://vinebot_description/meshes/rubber_rigth_middle_1.stl" scale="0.001 0.001 0.001"/>
      </geometry>
    </collision>
  </link>

  <link name="left_middle_1">
    <inertial>
      <origin rpy="0 0 0" xyz="5.922538787173082e-08 0.011699665940288206 -1.5836558509008114e-08"/>
      <mass value="0.5239439717413419"/>
      <inertia ixx="0.000916" ixy="0.0" ixz="-0.0" iyy="0.001378" iyz="-0.0" izz="0.000916"/>
    </inertial>
    <visual>
      <origin rpy="0 0 0" xyz="-0.361346 -0.195748 -0.133643"/>
      <geometry>
        <mesh filename="package://vinebot_description/meshes/left_middle_1.stl" scale="0.001 0.001 0.001"/>
      </geometry>
      <material name="silver"/>
    </visual>
    <collision>
      <origin rpy="0 0 0" xyz="-0.361346 -0.195748 -0.133643"/>
      <geometry>
        <mesh filename="package://vinebot_description/meshes/left_middle_1.stl" scale="0.001 0.001 0.001"/>
      </geometry>
    </collision>
  </link>

  <link name="rubber_left_middle_1">
    <inertial>
      <origin rpy="0 0 0" xyz="-7.859725481562663e-09 0.02700014582950408 -1.5544240267173492e-07"/>
      <mass value="1.3322018275318805"/>
      <inertia ixx="0.008837" ixy="-0.0" ixz="0.0" iyy="0.015831" iyz="0.0" izz="0.008837"/>
    </inertial>
    <visual>
      <origin rpy="0 0 0" xyz="-0.361346 -0.179895 -0.133643"/>
      <geometry>
        <mesh filename="package://vinebot_description/meshes/rubber_left_middle_1.stl" scale="0.001 0.001 0.001"/>
      </geometry>
      <material name="black"/>
    </visual>
    <collision>
      <origin rpy="0 0 0" xyz="-0.361346 -0.179895 -0.133643"/>
      <geometry>
        <mesh filename="package://vinebot_description/meshes/rubber_left_middle_1.stl" scale="0.001 0.001 0.001"/>
      </geometry>
    </collision>
  </link>

  <link name="box_cover_1">
    <inertial>
      <origin rpy="0 0 0" xyz="0.38420073940527333 0.10938180614612773 -0.007044227591617158"/>
      <mass value="7.618053194179163"/>
      <inertia ixx="0.077837" ixy="-1.8e-05" ixz="0.000345" iyy="0.526952" iyz="6.9e-05" izz="0.600556"/>
    </inertial>
    <visual>
      <origin rpy="0 0 0" xyz="0.09 0.109252 -0.368748"/>
      <geometry>
        <mesh filename="package://vinebot_description/meshes/box_cover_1.stl" scale="0.001 0.001 0.001"/>
      </geometry>
      <material name="silver"/>
    </visual>
    <collision>
      <origin rpy="0 0 0" xyz="0.09 0.109252 -0.368748"/>
      <geometry>
        <mesh filename="package://vinebot_description/meshes/box_cover_1.stl" scale="0.001 0.001 0.001"/>
      </geometry>
    </collision>
  </link>

  <link name="livox_laser">
    <inertial>
      <origin rpy="0 0 0" xyz="-0.13986365188962635 0.14255852645544653 0.12358394887627916"/>
      <mass value="4.964219605335798"/>
      <inertia ixx="0.016911" ixy="3.3e-05" ixz="-3.6e-05" iyy="0.017001" iyz="-2.2e-05" izz="0.012497"/>
    </inertial>
    <visual>
      <origin rpy="0 0 0" xyz="-0.706  0.141613 -0.382387"/>
      <geometry>
        <mesh filename="package://vinebot_description/meshes/livox_sensor_1.stl" scale="0.001 0.001 0.001"/>
      </geometry>
      <material name="silver"/>
    </visual>
    <collision>
      <origin rpy="0 0 0" xyz="-0.706 0.14163 -0.382387"/>
      <geometry>
        <mesh filename="package://vinebot_description/meshes/livox_sensor_1.stl" scale="0.001 0.001 0.001"/>
      </geometry>
    </collision>
  </link>

  <link name="imu_link">
    <visual>
      <geometry>
        <box size="0.05 0.1 0.05"/>
      </geometry>
      <material name="silver"/>
    </visual>
    <collision>
      <geometry>
        <box size="0.05 0.1 0.05"/>
      </geometry>
    </collision>
    <inertial>
      <mass value="0.01"/>
      <inertia ixx="0.145833" ixy="0.0" ixz="0.0" iyy="0.145833" iyz="0.0" izz="0.125"/>
    </inertial>
  </link>

  <link name="left_motor_with_gear_1">
    <inertial>
      <origin rpy="0 0 0" xyz="0.02113068020393443 -0.044340273375634114 -0.005108857414437312"/>
      <mass value="9.813113310184008"/>
      <inertia ixx="0.018602" ixy="-0.001018" ixz="-0.007531" iyy="0.069979" iyz="-0.000386" izz="0.062434"/>
    </inertial>
    <visual>
      <origin rpy="0 0 0" xyz="0.002926 -0.100748 -0.237151"/>
      <geometry>
        <mesh filename="package://vinebot_description/meshes/left_motor_with_gear_1.stl" scale="0.001 0.001 0.001"/>
      </geometry>
      <material name="silver"/>
    </visual>
    <collision>
      <origin rpy="0 0 0" xyz="0.002926 -0.100748 -0.237151"/>
      <geometry>
        <mesh filename="package://vinebot_description/meshes/left_motor_with_gear_1.stl" scale="0.001 0.001 0.001"/>
      </geometry>
    </collision>
  </link>

  <link name="right_motor_with_gear_1">
    <inertial>
      <origin rpy="0 0 0" xyz="0.013588464939077081 0.047239287684334795 -0.0034589170404338287"/>
      <mass value="9.816915603343025"/>
      <inertia ixx="0.018971" ixy="-0.000517" ixz="-0.008787" iyy="0.070368" iyz="-0.000331" izz="0.062421"/>
    </inertial>
    <visual>
      <origin rpy="0 0 0" xyz="-0.005949 0.104252 -0.233735"/>
      <geometry>
        <mesh filename="package://vinebot_description/meshes/right_motor_with_gear_1.stl" scale="0.001 0.001 0.001"/>
      </geometry>
      <material name="silver"/>
    </visual>
    <collision>
      <origin rpy="0 0 0" xyz="-0.005949 0.104252 -0.233735"/>
      <geometry>
        <mesh filename="package://vinebot_description/meshes/right_motor_with_gear_1.stl" scale="0.001 0.001 0.001"/>
      </geometry>
    </collision>
  </link>

  <joint name="right_back_to_base" type="continuous">
    <origin rpy="0 0 0" xyz="0.005176 -0.204252 0.133306"/>
    <parent link="base_link"/>
    <child link="right_back_1"/>
    <axis xyz="-0.0 1.0 0.0"/>
  </joint>

  <joint name="Rigid2" type="fixed">
    <origin rpy="0 0 0" xyz="0.0 -0.025853 0.0"/>
    <parent link="right_back_1"/>
    <child link="rubber_right_back_1"/>
  </joint>

  <joint name="left_back_to_base" type="continuous">
    <origin rpy="0 0 0" xyz="0.005176 0.195748 0.133306"/>
    <parent link="base_link"/>
    <child link="left_back_1"/>
    <axis xyz="0.0 1.0 -0.0"/>
  </joint>

  <joint name="Rigid3" type="fixed">
    <origin rpy="0 0 0" xyz="0.0 0.039252 0.0"/>
    <parent link="left_back_1"/>
    <child link="rubber_left_back_1"/>
  </joint>

  <joint name="right_front_to_base" type="continuous">
    <origin rpy="0 0 0" xyz="0.716 -0.204252 0.133748"/>
    <parent link="base_link"/>
    <child link="right_front_1"/>
    <axis xyz="0.0 1.0 -0.0"/>
  </joint>

  <joint name="Rigid6" type="fixed">
    <origin rpy="0 0 0" xyz="0.0 0.029252 0.0"/>
    <parent link="right_front_1"/>
    <child link="rubber_right_front_1"/>
  </joint>

  <joint name="left_front_to_base" type="continuous">
    <origin rpy="0 0 0" xyz="0.716 0.205748 0.133748"/>
    <parent link="base_link"/>
    <child link="left_front_1"/>
    <axis xyz="0.0 1.0 -0.0"/>
  </joint>

  <joint name="Rigid8" type="fixed">
    <origin rpy="0 0 0" xyz="0.0 -0.025853 0.0"/>
    <parent link="left_front_1"/>
    <child link="rubber_left_front_1"/>
  </joint>

  <joint name="rigth_middle_to_base" type="continuous">
    <origin rpy="0 0 0" xyz="0.361346 -0.204252 0.133643"/>
    <parent link="base_link"/>
    <child link="rigth_middle_1"/>
    <axis xyz="-0.0 1.0 0.0"/>
  </joint>

  <joint name="Rigid10" type="fixed">
    <origin rpy="0 0 0" xyz="0.0 -0.025853 0.0"/>
    <parent link="rigth_middle_1"/>
    <child link="rubber_rigth_middle_1"/>
  </joint>

  <joint name="left_middle_to_base" type="continuous">
    <origin rpy="0 0 0" xyz="0.361346 0.195748 0.133643"/>
    <parent link="base_link"/>
    <child link="left_middle_1"/>
    <axis xyz="0.0 1.0 -0.0"/>
  </joint>

  <joint name="Rigid12" type="fixed">
    <origin rpy="0 0 0" xyz="0.0 -0.015853 0.0"/>
    <parent link="left_middle_1"/>
    <child link="rubber_left_middle_1"/>
  </joint>

  <joint name="Rigid13" type="fixed">
    <origin rpy="0 0 0" xyz="-0.09 -0.109252 0.368748"/>
    <parent link="base_link"/>
    <child link="box_cover_1"/>
  </joint>

  <joint name="Rigid14" type="fixed">
    <origin rpy="0 0 0" xyz="0.796 -0.032361 0.013639"/>
    <parent link="box_cover_1"/>
    <child link="livox_laser"/>
  </joint>

  <joint name="Rigid15" type="fixed">
    <origin rpy="0 0 0" xyz="-0.002926 0.100748 0.237151"/>
    <parent link="base_link"/>
    <child link="left_motor_with_gear_1"/>
  </joint>

  <joint name="Rigid16" type="fixed">
    <origin rpy="0 0 0" xyz="0.005949 -0.104252 0.233735"/>
    <parent link="base_link"/>
    <child link="right_motor_with_gear_1"/>
  </joint>

  <!-- camera integration -->
  <link name="camera_base_link">
    <visual>
      <geometry>
        <box size="0.03 0.03 0.03"/>
      </geometry>
      <material name="blue"/>
    </visual>
    <collision>
      <geometry>
        <box size="0.03 0.03 0.03"/>
      </geometry>
    </collision>
    <inertial>
      <mass value="0.01"/>
      <inertia ixx="1e-5" ixy="0" ixz="0" iyy="1e-5" iyz="0" izz="1e-5"/>
    </inertial>
  </link>

  <!-- optional original realsense macro kept disabled -->
  

  <joint name="camera_base_to_box_cover_1" type="fixed">
    <parent link="box_cover_1"/>
    <child link="camera_base_link"/>
    <origin xyz="0.83 0.11 -0.068" rpy="0.0 0.0 0.0"/>
  </joint>

  <link name="front_camera_link">
    <visual>
      <origin xyz="0 0 0" rpy="0 0 0"/>
      <geometry>
        <box size="0.04 0.04 0.04"/>
      </geometry>
      <material name="black"/>
    </visual>
    <collision>
      <origin xyz="0 0 0" rpy="0 0 0"/>
      <geometry>
        <box size="0.04 0.04 0.04"/>
      </geometry>
    </collision>
    <inertial>
      <origin xyz="0 0 0" rpy="0 0 0"/>
      <mass value="0.05"/>
      <inertia ixx="1e-4" ixy="0" ixz="0" iyy="1e-4" iyz="0" izz="1e-4"/>
    </inertial>
  </link>

  <joint name="front_camera_joint" type="fixed">
    <parent link="camera_base_link"/>
    <child link="front_camera_link"/>
    <origin xyz="0.15 0.00 0.05" rpy="0 0 0"/>
  </joint>

  <link name="front_camera_optical_frame"/>
  <joint name="front_camera_optical_joint" type="fixed">
    <parent link="front_camera_link"/>
    <child link="front_camera_optical_frame"/>
    <origin xyz="0 0 0" rpy="-1.5708 0 -1.5708"/>
  </joint>

  <link name="left_camera_link">
    <visual>
      <origin xyz="0 0 0" rpy="0 0 0"/>
      <geometry>
        <box size="0.04 0.04 0.04"/>
      </geometry>
      <material name="blue"/>
    </visual>
    <collision>
      <origin xyz="0 0 0" rpy="0 0 0"/>
      <geometry>
        <box size="0.04 0.04 0.04"/>
      </geometry>
    </collision>
    <inertial>
      <origin xyz="0 0 0" rpy="0 0 0"/>
      <mass value="0.05"/>
      <inertia ixx="1e-4" ixy="0" ixz="0" iyy="1e-4" iyz="0" izz="1e-4"/>
    </inertial>
  </link>

  <joint name="left_camera_joint" type="fixed">
    <parent link="camera_base_link"/>
    <child link="left_camera_link"/>
    <origin xyz="0.10 0.10 0.05" rpy="0 0 1.5708"/>
  </joint>

  <link name="left_camera_optical_frame"/>
  <joint name="left_camera_optical_joint" type="fixed">
    <parent link="left_camera_link"/>
    <child link="left_camera_optical_frame"/>
    <origin xyz="0 0 0" rpy="-1.5708 0 -1.5708"/>
  </joint>

  <link name="right_camera_link">
    <visual>
      <origin xyz="0 0 0" rpy="0 0 0"/>
      <geometry>
        <box size="0.04 0.04 0.04"/>
      </geometry>
      <material name="green"/>
    </visual>
    <collision>
      <origin xyz="0 0 0" rpy="0 0 0"/>
      <geometry>
        <box size="0.04 0.04 0.04"/>
      </geometry>
    </collision>
    <inertial>
      <origin xyz="0 0 0" rpy="0 0 0"/>
      <mass value="0.05"/>
      <inertia ixx="1e-4" ixy="0" ixz="0" iyy="1e-4" iyz="0" izz="1e-4"/>
    </inertial>
  </link>

  <joint name="right_camera_joint" type="fixed">
    <parent link="camera_base_link"/>
    <child link="right_camera_link"/>
    <origin xyz="0.10 -0.10 0.05" rpy="0 0 -1.5708"/>
  </joint>

  <link name="right_camera_optical_frame"/>
  <joint name="right_camera_optical_joint" type="fixed">
    <parent link="right_camera_link"/>
    <child link="right_camera_optical_frame"/>
    <origin xyz="0 0 0" rpy="-1.5708 0 -1.5708"/>
  </joint>

  <link name="rear_camera_link">
    <visual>
      <origin xyz="0 0 0" rpy="0 0 0"/>
      <geometry>
        <box size="0.04 0.04 0.04"/>
      </geometry>
      <material name="red"/>
    </visual>
    <collision>
      <origin xyz="0 0 0" rpy="0 0 0"/>
      <geometry>
        <box size="0.04 0.04 0.04"/>
      </geometry>
    </collision>
    <inertial>
      <origin xyz="0 0 0" rpy="0 0 0"/>
      <mass value="0.05"/>
      <inertia ixx="1e-4" ixy="0" ixz="0" iyy="1e-4" iyz="0" izz="1e-4"/>
    </inertial>
  </link>

  <joint name="rear_camera_joint" type="fixed">
    <parent link="camera_base_link"/>
    <child link="rear_camera_link"/>
    <origin xyz="-0.12 0.00 0.05" rpy="0 0 3.1416"/>
  </joint>

  <link name="rear_camera_optical_frame"/>
  <joint name="rear_camera_optical_joint" type="fixed">
    <parent link="rear_camera_link"/>
    <child link="rear_camera_optical_frame"/>
    <origin xyz="0 0 0" rpy="-1.5708 0 -1.5708"/>
  </joint>

  <joint name="imu_joint" type="fixed">
    <parent link="box_cover_1"/>
    <child link="imu_link"/>
    <origin xyz="0.83 0.11 -0.068" rpy="0 0 0"/>
  </joint>

  <!-- livox frame -->
  <link name="livox_frame"/>

  <joint name="livox_lidar_to_livox_frame" type="fixed">
    <parent link="livox_laser"/>
    <child link="livox_frame"/>
    <origin xyz="0.05 0.14 0.07" rpy="0.0 0.0 0.0"/>
  </joint>

</robot>

